[2023-11-13 20:52:46,523] ERROR _log() L96   Error on request:
Traceback (most recent call last):
  File "/home/ubuntu/miniconda3/lib/python3.11/site-packages/werkzeug/serving.py", line 362, in run_wsgi
    execute(self.server.app)
  File "/home/ubuntu/miniconda3/lib/python3.11/site-packages/werkzeug/serving.py", line 323, in execute
    application_iter = app(environ, start_response)
                       ^^^^^^^^^^^^^^^^^^^^^^^^^^^^
  File "/home/ubuntu/miniconda3/lib/python3.11/site-packages/flask/cli.py", line 906, in app
    raise err from None
  File "/home/ubuntu/miniconda3/lib/python3.11/site-packages/werkzeug/serving.py", line 362, in run_wsgi
    execute(self.server.app)
  File "/home/ubuntu/miniconda3/lib/python3.11/site-packages/werkzeug/serving.py", line 323, in execute
    application_iter = app(environ, start_response)
                       ^^^^^^^^^^^^^^^^^^^^^^^^^^^^
  File "/home/ubuntu/miniconda3/lib/python3.11/site-packages/flask/cli.py", line 906, in app
    raise err from None
  File "/home/ubuntu/miniconda3/lib/python3.11/site-packages/werkzeug/serving.py", line 362, in run_wsgi
    execute(self.server.app)
  File "/home/ubuntu/miniconda3/lib/python3.11/site-packages/werkzeug/serving.py", line 323, in execute
    application_iter = app(environ, start_response)
                       ^^^^^^^^^^^^^^^^^^^^^^^^^^^^
  File "/home/ubuntu/miniconda3/lib/python3.11/site-packages/flask/cli.py", line 906, in app
    raise err from None
  File "/home/ubuntu/miniconda3/lib/python3.11/site-packages/werkzeug/serving.py", line 362, in run_wsgi
    execute(self.server.app)
  File "/home/ubuntu/miniconda3/lib/python3.11/site-packages/werkzeug/serving.py", line 323, in execute
    application_iter = app(environ, start_response)
                       ^^^^^^^^^^^^^^^^^^^^^^^^^^^^
  File "/home/ubuntu/miniconda3/lib/python3.11/site-packages/flask/cli.py", line 906, in app
    raise err from None
  File "/home/ubuntu/miniconda3/lib/python3.11/site-packages/werkzeug/serving.py", line 362, in run_wsgi
    execute(self.server.app)
  File "/home/ubuntu/miniconda3/lib/python3.11/site-packages/werkzeug/serving.py", line 323, in execute
    application_iter = app(environ, start_response)
                       ^^^^^^^^^^^^^^^^^^^^^^^^^^^^
  File "/home/ubuntu/miniconda3/lib/python3.11/site-packages/flask/cli.py", line 906, in app
    raise err from None
  File "/home/ubuntu/miniconda3/lib/python3.11/site-packages/werkzeug/serving.py", line 362, in run_wsgi
    execute(self.server.app)
  File "/home/ubuntu/miniconda3/lib/python3.11/site-packages/werkzeug/serving.py", line 323, in execute
    application_iter = app(environ, start_response)
                       ^^^^^^^^^^^^^^^^^^^^^^^^^^^^
  File "/home/ubuntu/miniconda3/lib/python3.11/site-packages/flask/cli.py", line 906, in app
    raise err from None
  File "/home/ubuntu/miniconda3/lib/python3.11/site-packages/flask/cli.py", line 897, in run_command
    app = info.load_app()
          ^^^^^^^^^^^^^^^
  File "/home/ubuntu/miniconda3/lib/python3.11/site-packages/flask/cli.py", line 312, in load_app
    app = locate_app(import_name, None, raise_if_not_found=False)
          ^^^^^^^^^^^^^^^^^^^^^^^^^^^^^^^^^^^^^^^^^^^^^^^^^^^^^^^
  File "/home/ubuntu/miniconda3/lib/python3.11/site-packages/flask/cli.py", line 223, in locate_app
    raise NoAppException(
flask.cli.NoAppException: While importing 'app', an ImportError was raised:

Traceback (most recent call last):
  File "/home/ubuntu/miniconda3/lib/python3.11/site-packages/flask/cli.py", line 218, in locate_app
    __import__(module_name)
  File "/mnt/g/My Drive/Doutorado/Teaching/SoftEng4IntSysPos/exemplo_mvp/api/app.py", line 9, in <module>
    from schemas import *
  File "/mnt/g/My Drive/Doutorado/Teaching/SoftEng4IntSysPos/exemplo_mvp/api/schemas/__init__.py", line 1, in <module>
    from schemas.paciente_schema import PacienteSchema,  PacienteBuscaSchema, PacienteViewSchema, PacienteDelSchema, \
ImportError: cannot import name 'predict_diabetes' from 'schemas.paciente_schema' (/mnt/g/My Drive/Doutorado/Teaching/SoftEng4IntSysPos/exemplo_mvp/api/schemas/paciente_schema.py) - call_trace=/home/ubuntu/miniconda3/lib/python3.11/site-packages/werkzeug/_internal.py L96  
[2023-11-13 20:53:34,353] INFO _log() L96    * Detected change in '/mnt/g/My Drive/Doutorado/Teaching/SoftEng4IntSysPos/exemplo_mvp/api/schemas/paciente_schema.py', reloading - call_trace=/home/ubuntu/miniconda3/lib/python3.11/site-packages/werkzeug/_internal.py L96  
[2023-11-13 20:53:50,300] INFO _log() L96   127.0.0.1 - - [13/Nov/2023 20:53:50] "[32mGET / HTTP/1.1[0m" 302 - - call_trace=/home/ubuntu/miniconda3/lib/python3.11/site-packages/werkzeug/_internal.py L96  
[2023-11-13 20:53:50,323] INFO _log() L96   127.0.0.1 - - [13/Nov/2023 20:53:50] "[32mGET /openapi HTTP/1.1[0m" 308 - - call_trace=/home/ubuntu/miniconda3/lib/python3.11/site-packages/werkzeug/_internal.py L96  
[2023-11-13 20:53:50,346] INFO _log() L96   127.0.0.1 - - [13/Nov/2023 20:53:50] "GET /openapi/ HTTP/1.1" 200 - - call_trace=/home/ubuntu/miniconda3/lib/python3.11/site-packages/werkzeug/_internal.py L96  
[2023-11-13 20:56:49,533] INFO _log() L96   127.0.0.1 - - [13/Nov/2023 20:56:49] "GET /pacientes HTTP/1.1" 200 - - call_trace=/home/ubuntu/miniconda3/lib/python3.11/site-packages/werkzeug/_internal.py L96  
[2023-11-13 20:57:08,508] INFO _log() L96   127.0.0.1 - - [13/Nov/2023 20:57:08] "GET /pacientes HTTP/1.1" 200 - - call_trace=/home/ubuntu/miniconda3/lib/python3.11/site-packages/werkzeug/_internal.py L96  
[2023-11-13 20:57:15,570] INFO _log() L96   127.0.0.1 - - [13/Nov/2023 20:57:15] "GET /pacientes HTTP/1.1" 200 - - call_trace=/home/ubuntu/miniconda3/lib/python3.11/site-packages/werkzeug/_internal.py L96  
[2023-11-13 20:57:28,996] INFO _log() L96   127.0.0.1 - - [13/Nov/2023 20:57:28] "GET /pacientes HTTP/1.1" 200 - - call_trace=/home/ubuntu/miniconda3/lib/python3.11/site-packages/werkzeug/_internal.py L96  
[2023-11-13 20:57:32,811] INFO _log() L96   127.0.0.1 - - [13/Nov/2023 20:57:32] "GET /pacientes HTTP/1.1" 200 - - call_trace=/home/ubuntu/miniconda3/lib/python3.11/site-packages/werkzeug/_internal.py L96  
[2023-11-13 20:57:35,504] INFO _log() L96   127.0.0.1 - - [13/Nov/2023 20:57:35] "GET /pacientes HTTP/1.1" 200 - - call_trace=/home/ubuntu/miniconda3/lib/python3.11/site-packages/werkzeug/_internal.py L96  
[2023-11-13 20:57:40,288] INFO _log() L96   127.0.0.1 - - [13/Nov/2023 20:57:40] "GET /pacientes HTTP/1.1" 200 - - call_trace=/home/ubuntu/miniconda3/lib/python3.11/site-packages/werkzeug/_internal.py L96  
[2023-11-13 21:02:05,972] INFO _log() L96   127.0.0.1 - - [13/Nov/2023 21:02:05] "GET /pacientes HTTP/1.1" 200 - - call_trace=/home/ubuntu/miniconda3/lib/python3.11/site-packages/werkzeug/_internal.py L96  
[2023-11-13 21:06:32,472] INFO _log() L96   127.0.0.1 - - [13/Nov/2023 21:06:32] "GET /pacientes HTTP/1.1" 200 - - call_trace=/home/ubuntu/miniconda3/lib/python3.11/site-packages/werkzeug/_internal.py L96  
[2023-11-13 21:06:46,905] INFO _log() L96   127.0.0.1 - - [13/Nov/2023 21:06:46] "DELETE /paciente?name=Maria HTTP/1.1" 200 - - call_trace=/home/ubuntu/miniconda3/lib/python3.11/site-packages/werkzeug/_internal.py L96  
[2023-11-13 21:06:47,377] INFO _log() L96   127.0.0.1 - - [13/Nov/2023 21:06:47] "GET /pacientes HTTP/1.1" 200 - - call_trace=/home/ubuntu/miniconda3/lib/python3.11/site-packages/werkzeug/_internal.py L96  
[2023-11-13 21:06:47,867] WARNING delete_paciente() L178  Erro ao deletar paciente 'Maria', Paciente n√£o encontrado na base :/ - call_trace=/mnt/g/My Drive/Doutorado/Teaching/SoftEng4IntSysPos/exemplo_mvp/api/app.py L178 
[2023-11-13 21:06:47,869] INFO _log() L96   127.0.0.1 - - [13/Nov/2023 21:06:47] "[33mDELETE /paciente?name=Maria HTTP/1.1[0m" 404 - - call_trace=/home/ubuntu/miniconda3/lib/python3.11/site-packages/werkzeug/_internal.py L96  
[2023-11-13 21:06:49,109] WARNING delete_paciente() L178  Erro ao deletar paciente 'Maria', Paciente n√£o encontrado na base :/ - call_trace=/mnt/g/My Drive/Doutorado/Teaching/SoftEng4IntSysPos/exemplo_mvp/api/app.py L178 
[2023-11-13 21:06:49,110] INFO _log() L96   127.0.0.1 - - [13/Nov/2023 21:06:49] "[33mDELETE /paciente?name=Maria HTTP/1.1[0m" 404 - - call_trace=/home/ubuntu/miniconda3/lib/python3.11/site-packages/werkzeug/_internal.py L96  
[2023-11-13 21:06:54,561] INFO _log() L96   127.0.0.1 - - [13/Nov/2023 21:06:54] "DELETE /paciente?name=Lucas HTTP/1.1" 200 - - call_trace=/home/ubuntu/miniconda3/lib/python3.11/site-packages/werkzeug/_internal.py L96  
[2023-11-13 21:06:55,004] WARNING get_pacientes() L50   N√£o h√° pacientes cadastrados na base :/ - call_trace=/mnt/g/My Drive/Doutorado/Teaching/SoftEng4IntSysPos/exemplo_mvp/api/app.py L50  
[2023-11-13 21:06:55,006] INFO _log() L96   127.0.0.1 - - [13/Nov/2023 21:06:55] "[33mGET /pacientes HTTP/1.1[0m" 404 - - call_trace=/home/ubuntu/miniconda3/lib/python3.11/site-packages/werkzeug/_internal.py L96  
[2023-11-13 21:10:05,100] WARNING get_pacientes() L50   N√£o h√° pacientes cadastrados na base :/ - call_trace=/mnt/g/My Drive/Doutorado/Teaching/SoftEng4IntSysPos/exemplo_mvp/api/app.py L50  
[2023-11-13 21:10:05,101] INFO _log() L96   127.0.0.1 - - [13/Nov/2023 21:10:05] "[33mGET /pacientes HTTP/1.1[0m" 404 - - call_trace=/home/ubuntu/miniconda3/lib/python3.11/site-packages/werkzeug/_internal.py L96  
[2023-11-13 21:10:44,540] INFO _log() L96    * Detected change in '/mnt/g/My Drive/Doutorado/Teaching/SoftEng4IntSysPos/exemplo_mvp/api/schemas/paciente_schema.py', reloading - call_trace=/home/ubuntu/miniconda3/lib/python3.11/site-packages/werkzeug/_internal.py L96  
[2023-11-13 21:10:46,365] INFO _log() L96   127.0.0.1 - - [13/Nov/2023 21:10:46] "[35m[1mGET /pacientes HTTP/1.1[0m" 500 - - call_trace=/home/ubuntu/miniconda3/lib/python3.11/site-packages/werkzeug/_internal.py L96  
