[2023-12-07 16:41:39,248] INFO _log() L224  127.0.0.1 - - [07/Dec/2023 16:41:39] "[36mGET /openapi/static/images/redoc.svg HTTP/1.1[0m" 304 - - call_trace=C:\Python311\Lib\site-packages\werkzeug\_internal.py L224 
[2023-12-07 16:41:39,301] INFO _log() L224  127.0.0.1 - - [07/Dec/2023 16:41:39] "[36mGET /openapi/static/images/swagger.svg HTTP/1.1[0m" 304 - - call_trace=C:\Python311\Lib\site-packages\werkzeug\_internal.py L224 
[2023-12-07 16:41:39,391] INFO _log() L224  127.0.0.1 - - [07/Dec/2023 16:41:39] "[36mGET /openapi/static/images/rapidoc.svg HTTP/1.1[0m" 304 - - call_trace=C:\Python311\Lib\site-packages\werkzeug\_internal.py L224 
[2023-12-07 16:41:42,808] ERROR log_exception() L1449 Exception on /avaliacao [POST] - call_trace=C:\Python311\Lib\site-packages\flask\app.py L1449
Traceback (most recent call last):
  File "C:\Python311\Lib\site-packages\flask\app.py", line 2073, in wsgi_app
    response = self.full_dispatch_request()
               ^^^^^^^^^^^^^^^^^^^^^^^^^^^^
  File "C:\Python311\Lib\site-packages\flask\app.py", line 1519, in full_dispatch_request
    rv = self.handle_user_exception(e)
         ^^^^^^^^^^^^^^^^^^^^^^^^^^^^^
  File "C:\Python311\Lib\site-packages\flask_cors\extension.py", line 165, in wrapped_function
    return cors_after_request(app.make_response(f(*args, **kwargs)))
                                                ^^^^^^^^^^^^^^^^^^
  File "C:\Python311\Lib\site-packages\flask\app.py", line 1517, in full_dispatch_request
    rv = self.dispatch_request()
         ^^^^^^^^^^^^^^^^^^^^^^^
  File "C:\Python311\Lib\site-packages\flask\app.py", line 1503, in dispatch_request
    return self.ensure_sync(self.view_functions[rule.endpoint])(**req.view_args)
           ^^^^^^^^^^^^^^^^^^^^^^^^^^^^^^^^^^^^^^^^^^^^^^^^^^^^^^^^^^^^^^^^^^^^^
  File "C:\Python311\Lib\site-packages\flask_openapi3\scaffold.py", line 191, in wrapper
    resp = _do_wrapper(
           ^^^^^^^^^^^^
  File "C:\Python311\Lib\site-packages\flask_openapi3\do_wrapper.py", line 135, in _do_wrapper
    response = func(**request_kwargs)
               ^^^^^^^^^^^^^^^^^^^^^^
  File "C:\Users\aluga.com\Desktop\mvp-qualidade-seguranca-sistemas-inteligentes\exemplo_mvp\api\app.py", line 78, in predict
    dataset = carregador().carregar_dados(ml_path)
              ^^^^^^^^^^^^
TypeError: 'module' object is not callable
[2023-12-07 16:41:42,838] INFO _log() L224  127.0.0.1 - - [07/Dec/2023 16:41:42] "[35m[1mPOST /avaliacao HTTP/1.1[0m" 500 - - call_trace=C:\Python311\Lib\site-packages\werkzeug\_internal.py L224 
[2023-12-07 16:43:41,982] INFO _log() L224   * Running on all addresses (0.0.0.0)
   WARNING: This is a development server. Do not use it in a production deployment.
 * Running on http://127.0.0.1:5000
 * Running on http://192.168.0.179:5000 (Press CTRL+C to quit) - call_trace=C:\Python311\Lib\site-packages\werkzeug\_internal.py L224 
[2023-12-07 16:43:47,119] ERROR log_exception() L1449 Exception on /avaliacao [POST] - call_trace=C:\Python311\Lib\site-packages\flask\app.py L1449
Traceback (most recent call last):
  File "C:\Python311\Lib\site-packages\flask\app.py", line 2073, in wsgi_app
    response = self.full_dispatch_request()
               ^^^^^^^^^^^^^^^^^^^^^^^^^^^^
  File "C:\Python311\Lib\site-packages\flask\app.py", line 1519, in full_dispatch_request
    rv = self.handle_user_exception(e)
         ^^^^^^^^^^^^^^^^^^^^^^^^^^^^^
  File "C:\Python311\Lib\site-packages\flask_cors\extension.py", line 165, in wrapped_function
    return cors_after_request(app.make_response(f(*args, **kwargs)))
                                                ^^^^^^^^^^^^^^^^^^
  File "C:\Python311\Lib\site-packages\flask\app.py", line 1517, in full_dispatch_request
    rv = self.dispatch_request()
         ^^^^^^^^^^^^^^^^^^^^^^^
  File "C:\Python311\Lib\site-packages\flask\app.py", line 1503, in dispatch_request
    return self.ensure_sync(self.view_functions[rule.endpoint])(**req.view_args)
           ^^^^^^^^^^^^^^^^^^^^^^^^^^^^^^^^^^^^^^^^^^^^^^^^^^^^^^^^^^^^^^^^^^^^^
  File "C:\Python311\Lib\site-packages\flask_openapi3\scaffold.py", line 191, in wrapper
    resp = _do_wrapper(
           ^^^^^^^^^^^^
  File "C:\Python311\Lib\site-packages\flask_openapi3\do_wrapper.py", line 135, in _do_wrapper
    response = func(**request_kwargs)
               ^^^^^^^^^^^^^^^^^^^^^^
  File "C:\Users\aluga.com\Desktop\mvp-qualidade-seguranca-sistemas-inteligentes\exemplo_mvp\api\app.py", line 84, in predict
    percentual_teste)
    ^^^^^^^^^^^^^^^^
NameError: name 'percentual_teste' is not defined
[2023-12-07 16:43:47,144] INFO _log() L224  127.0.0.1 - - [07/Dec/2023 16:43:47] "[35m[1mPOST /avaliacao HTTP/1.1[0m" 500 - - call_trace=C:\Python311\Lib\site-packages\werkzeug\_internal.py L224 
[2023-12-07 16:43:48,269] ERROR log_exception() L1449 Exception on /avaliacao [POST] - call_trace=C:\Python311\Lib\site-packages\flask\app.py L1449
Traceback (most recent call last):
  File "C:\Python311\Lib\site-packages\flask\app.py", line 2073, in wsgi_app
    response = self.full_dispatch_request()
               ^^^^^^^^^^^^^^^^^^^^^^^^^^^^
  File "C:\Python311\Lib\site-packages\flask\app.py", line 1519, in full_dispatch_request
    rv = self.handle_user_exception(e)
         ^^^^^^^^^^^^^^^^^^^^^^^^^^^^^
  File "C:\Python311\Lib\site-packages\flask_cors\extension.py", line 165, in wrapped_function
    return cors_after_request(app.make_response(f(*args, **kwargs)))
                                                ^^^^^^^^^^^^^^^^^^
  File "C:\Python311\Lib\site-packages\flask\app.py", line 1517, in full_dispatch_request
    rv = self.dispatch_request()
         ^^^^^^^^^^^^^^^^^^^^^^^
  File "C:\Python311\Lib\site-packages\flask\app.py", line 1503, in dispatch_request
    return self.ensure_sync(self.view_functions[rule.endpoint])(**req.view_args)
           ^^^^^^^^^^^^^^^^^^^^^^^^^^^^^^^^^^^^^^^^^^^^^^^^^^^^^^^^^^^^^^^^^^^^^
  File "C:\Python311\Lib\site-packages\flask_openapi3\scaffold.py", line 191, in wrapper
    resp = _do_wrapper(
           ^^^^^^^^^^^^
  File "C:\Python311\Lib\site-packages\flask_openapi3\do_wrapper.py", line 135, in _do_wrapper
    response = func(**request_kwargs)
               ^^^^^^^^^^^^^^^^^^^^^^
  File "C:\Users\aluga.com\Desktop\mvp-qualidade-seguranca-sistemas-inteligentes\exemplo_mvp\api\app.py", line 84, in predict
    percentual_teste)
    ^^^^^^^^^^^^^^^^
NameError: name 'percentual_teste' is not defined
[2023-12-07 16:43:48,288] INFO _log() L224  127.0.0.1 - - [07/Dec/2023 16:43:48] "[35m[1mPOST /avaliacao HTTP/1.1[0m" 500 - - call_trace=C:\Python311\Lib\site-packages\werkzeug\_internal.py L224 
[2023-12-07 16:44:40,169] INFO _log() L224   * Running on all addresses (0.0.0.0)
   WARNING: This is a development server. Do not use it in a production deployment.
 * Running on http://127.0.0.1:5000
 * Running on http://192.168.0.179:5000 (Press CTRL+C to quit) - call_trace=C:\Python311\Lib\site-packages\werkzeug\_internal.py L224 
[2023-12-07 16:44:52,519] ERROR log_exception() L1449 Exception on /avaliacao [POST] - call_trace=C:\Python311\Lib\site-packages\flask\app.py L1449
Traceback (most recent call last):
  File "C:\Python311\Lib\site-packages\flask\app.py", line 2073, in wsgi_app
    response = self.full_dispatch_request()
               ^^^^^^^^^^^^^^^^^^^^^^^^^^^^
  File "C:\Python311\Lib\site-packages\flask\app.py", line 1519, in full_dispatch_request
    rv = self.handle_user_exception(e)
         ^^^^^^^^^^^^^^^^^^^^^^^^^^^^^
  File "C:\Python311\Lib\site-packages\flask_cors\extension.py", line 165, in wrapped_function
    return cors_after_request(app.make_response(f(*args, **kwargs)))
                                                ^^^^^^^^^^^^^^^^^^
  File "C:\Python311\Lib\site-packages\flask\app.py", line 1517, in full_dispatch_request
    rv = self.dispatch_request()
         ^^^^^^^^^^^^^^^^^^^^^^^
  File "C:\Python311\Lib\site-packages\flask\app.py", line 1503, in dispatch_request
    return self.ensure_sync(self.view_functions[rule.endpoint])(**req.view_args)
           ^^^^^^^^^^^^^^^^^^^^^^^^^^^^^^^^^^^^^^^^^^^^^^^^^^^^^^^^^^^^^^^^^^^^^
  File "C:\Python311\Lib\site-packages\flask_openapi3\scaffold.py", line 191, in wrapper
    resp = _do_wrapper(
           ^^^^^^^^^^^^
  File "C:\Python311\Lib\site-packages\flask_openapi3\do_wrapper.py", line 135, in _do_wrapper
    response = func(**request_kwargs)
               ^^^^^^^^^^^^^^^^^^^^^^
  File "C:\Users\aluga.com\Desktop\mvp-qualidade-seguranca-sistemas-inteligentes\exemplo_mvp\api\app.py", line 86, in predict
    model = Model().treinar_KNN(X_train, Y_train)
            ^^^^^^^^^^^^^^^^^^^^^^^^^^^^^^^^^^^^^
  File "C:\Users\aluga.com\Desktop\mvp-qualidade-seguranca-sistemas-inteligentes\exemplo_mvp\api\model\modelo.py", line 11, in treinar_KNN
    modelo = KNeighborsClassifier()
             ^^^^^^^^^^^^^^^^^^^^
NameError: name 'KNeighborsClassifier' is not defined
[2023-12-07 16:44:52,537] INFO _log() L224  127.0.0.1 - - [07/Dec/2023 16:44:52] "[35m[1mPOST /avaliacao HTTP/1.1[0m" 500 - - call_trace=C:\Python311\Lib\site-packages\werkzeug\_internal.py L224 
[2023-12-07 16:45:34,999] INFO _log() L224   * Running on all addresses (0.0.0.0)
   WARNING: This is a development server. Do not use it in a production deployment.
 * Running on http://127.0.0.1:5000
 * Running on http://192.168.0.179:5000 (Press CTRL+C to quit) - call_trace=C:\Python311\Lib\site-packages\werkzeug\_internal.py L224 
