[2023-12-07 16:45:40,065] ERROR log_exception() L1449 Exception on /avaliacao [POST] - call_trace=C:\Python311\Lib\site-packages\flask\app.py L1449
Traceback (most recent call last):
  File "C:\Python311\Lib\site-packages\flask\app.py", line 2073, in wsgi_app
    response = self.full_dispatch_request()
               ^^^^^^^^^^^^^^^^^^^^^^^^^^^^
  File "C:\Python311\Lib\site-packages\flask\app.py", line 1519, in full_dispatch_request
    rv = self.handle_user_exception(e)
         ^^^^^^^^^^^^^^^^^^^^^^^^^^^^^
  File "C:\Python311\Lib\site-packages\flask_cors\extension.py", line 165, in wrapped_function
    return cors_after_request(app.make_response(f(*args, **kwargs)))
                                                ^^^^^^^^^^^^^^^^^^
  File "C:\Python311\Lib\site-packages\flask\app.py", line 1517, in full_dispatch_request
    rv = self.dispatch_request()
         ^^^^^^^^^^^^^^^^^^^^^^^
  File "C:\Python311\Lib\site-packages\flask\app.py", line 1503, in dispatch_request
    return self.ensure_sync(self.view_functions[rule.endpoint])(**req.view_args)
           ^^^^^^^^^^^^^^^^^^^^^^^^^^^^^^^^^^^^^^^^^^^^^^^^^^^^^^^^^^^^^^^^^^^^^
  File "C:\Python311\Lib\site-packages\flask_openapi3\scaffold.py", line 191, in wrapper
    resp = _do_wrapper(
           ^^^^^^^^^^^^
  File "C:\Python311\Lib\site-packages\flask_openapi3\do_wrapper.py", line 135, in _do_wrapper
    response = func(**request_kwargs)
               ^^^^^^^^^^^^^^^^^^^^^^
  File "C:\Users\aluga.com\Desktop\mvp-qualidade-seguranca-sistemas-inteligentes\exemplo_mvp\api\app.py", line 90, in predict
    avaliacao = Avaliacao(
                ^^^^^^^^^
NameError: name 'Avaliacao' is not defined
[2023-12-07 16:45:40,119] INFO _log() L224  127.0.0.1 - - [07/Dec/2023 16:45:40] "[35m[1mPOST /avaliacao HTTP/1.1[0m" 500 - - call_trace=C:\Python311\Lib\site-packages\werkzeug\_internal.py L224 
[2023-12-07 16:46:38,408] INFO _log() L224   * Running on all addresses (0.0.0.0)
   WARNING: This is a development server. Do not use it in a production deployment.
 * Running on http://127.0.0.1:5000
 * Running on http://192.168.0.179:5000 (Press CTRL+C to quit) - call_trace=C:\Python311\Lib\site-packages\werkzeug\_internal.py L224 
[2023-12-07 16:46:40,560] ERROR log_exception() L1449 Exception on /avaliacao [POST] - call_trace=C:\Python311\Lib\site-packages\flask\app.py L1449
Traceback (most recent call last):
  File "C:\Python311\Lib\site-packages\flask\app.py", line 2073, in wsgi_app
    response = self.full_dispatch_request()
               ^^^^^^^^^^^^^^^^^^^^^^^^^^^^
  File "C:\Python311\Lib\site-packages\flask\app.py", line 1519, in full_dispatch_request
    rv = self.handle_user_exception(e)
         ^^^^^^^^^^^^^^^^^^^^^^^^^^^^^
  File "C:\Python311\Lib\site-packages\flask_cors\extension.py", line 165, in wrapped_function
    return cors_after_request(app.make_response(f(*args, **kwargs)))
                                                ^^^^^^^^^^^^^^^^^^
  File "C:\Python311\Lib\site-packages\flask\app.py", line 1517, in full_dispatch_request
    rv = self.dispatch_request()
         ^^^^^^^^^^^^^^^^^^^^^^^
  File "C:\Python311\Lib\site-packages\flask\app.py", line 1503, in dispatch_request
    return self.ensure_sync(self.view_functions[rule.endpoint])(**req.view_args)
           ^^^^^^^^^^^^^^^^^^^^^^^^^^^^^^^^^^^^^^^^^^^^^^^^^^^^^^^^^^^^^^^^^^^^^
  File "C:\Python311\Lib\site-packages\flask_openapi3\scaffold.py", line 191, in wrapper
    resp = _do_wrapper(
           ^^^^^^^^^^^^
  File "C:\Python311\Lib\site-packages\flask_openapi3\do_wrapper.py", line 135, in _do_wrapper
    response = func(**request_kwargs)
               ^^^^^^^^^^^^^^^^^^^^^^
  File "C:\Users\aluga.com\Desktop\mvp-qualidade-seguranca-sistemas-inteligentes\exemplo_mvp\api\app.py", line 95, in predict
    resultado=form.resultado,
              ^^^^^^^^^^^^^^
AttributeError: 'AvaliacaoSchema' object has no attribute 'resultado'
[2023-12-07 16:46:40,574] INFO _log() L224  127.0.0.1 - - [07/Dec/2023 16:46:40] "[35m[1mPOST /avaliacao HTTP/1.1[0m" 500 - - call_trace=C:\Python311\Lib\site-packages\werkzeug\_internal.py L224 
[2023-12-07 16:48:41,892] INFO _log() L224   * Running on all addresses (0.0.0.0)
   WARNING: This is a development server. Do not use it in a production deployment.
 * Running on http://127.0.0.1:5000
 * Running on http://192.168.0.179:5000 (Press CTRL+C to quit) - call_trace=C:\Python311\Lib\site-packages\werkzeug\_internal.py L224 
[2023-12-07 16:48:46,059] ERROR log_exception() L1449 Exception on /avaliacao [POST] - call_trace=C:\Python311\Lib\site-packages\flask\app.py L1449
Traceback (most recent call last):
  File "C:\Python311\Lib\site-packages\flask\app.py", line 2073, in wsgi_app
    response = self.full_dispatch_request()
               ^^^^^^^^^^^^^^^^^^^^^^^^^^^^
  File "C:\Python311\Lib\site-packages\flask\app.py", line 1519, in full_dispatch_request
    rv = self.handle_user_exception(e)
         ^^^^^^^^^^^^^^^^^^^^^^^^^^^^^
  File "C:\Python311\Lib\site-packages\flask_cors\extension.py", line 165, in wrapped_function
    return cors_after_request(app.make_response(f(*args, **kwargs)))
                                                ^^^^^^^^^^^^^^^^^^
  File "C:\Python311\Lib\site-packages\flask\app.py", line 1517, in full_dispatch_request
    rv = self.dispatch_request()
         ^^^^^^^^^^^^^^^^^^^^^^^
  File "C:\Python311\Lib\site-packages\flask\app.py", line 1503, in dispatch_request
    return self.ensure_sync(self.view_functions[rule.endpoint])(**req.view_args)
           ^^^^^^^^^^^^^^^^^^^^^^^^^^^^^^^^^^^^^^^^^^^^^^^^^^^^^^^^^^^^^^^^^^^^^
  File "C:\Python311\Lib\site-packages\flask_openapi3\scaffold.py", line 191, in wrapper
    resp = _do_wrapper(
           ^^^^^^^^^^^^
  File "C:\Python311\Lib\site-packages\flask_openapi3\do_wrapper.py", line 135, in _do_wrapper
    response = func(**request_kwargs)
               ^^^^^^^^^^^^^^^^^^^^^^
  File "C:\Users\aluga.com\Desktop\mvp-qualidade-seguranca-sistemas-inteligentes\exemplo_mvp\api\app.py", line 89, in predict
    avaliacao = Avaliacao(
                ^^^^^^^^^^
TypeError: __init__() got an unexpected keyword argument 'receita_total'
[2023-12-07 16:48:46,092] INFO _log() L224  127.0.0.1 - - [07/Dec/2023 16:48:46] "[35m[1mPOST /avaliacao HTTP/1.1[0m" 500 - - call_trace=C:\Python311\Lib\site-packages\werkzeug\_internal.py L224 
[2023-12-07 16:49:55,944] INFO _log() L224   * Running on all addresses (0.0.0.0)
   WARNING: This is a development server. Do not use it in a production deployment.
 * Running on http://127.0.0.1:5000
 * Running on http://192.168.0.179:5000 (Press CTRL+C to quit) - call_trace=C:\Python311\Lib\site-packages\werkzeug\_internal.py L224 
[2023-12-07 16:50:06,903] ERROR log_exception() L1449 Exception on /avaliacao [POST] - call_trace=C:\Python311\Lib\site-packages\flask\app.py L1449
Traceback (most recent call last):
  File "C:\Python311\Lib\site-packages\flask\app.py", line 2073, in wsgi_app
    response = self.full_dispatch_request()
               ^^^^^^^^^^^^^^^^^^^^^^^^^^^^
  File "C:\Python311\Lib\site-packages\flask\app.py", line 1519, in full_dispatch_request
    rv = self.handle_user_exception(e)
         ^^^^^^^^^^^^^^^^^^^^^^^^^^^^^
  File "C:\Python311\Lib\site-packages\flask_cors\extension.py", line 165, in wrapped_function
    return cors_after_request(app.make_response(f(*args, **kwargs)))
                                                ^^^^^^^^^^^^^^^^^^
  File "C:\Python311\Lib\site-packages\flask\app.py", line 1517, in full_dispatch_request
    rv = self.dispatch_request()
         ^^^^^^^^^^^^^^^^^^^^^^^
  File "C:\Python311\Lib\site-packages\flask\app.py", line 1503, in dispatch_request
    return self.ensure_sync(self.view_functions[rule.endpoint])(**req.view_args)
           ^^^^^^^^^^^^^^^^^^^^^^^^^^^^^^^^^^^^^^^^^^^^^^^^^^^^^^^^^^^^^^^^^^^^^
  File "C:\Python311\Lib\site-packages\flask_openapi3\scaffold.py", line 191, in wrapper
    resp = _do_wrapper(
           ^^^^^^^^^^^^
  File "C:\Python311\Lib\site-packages\flask_openapi3\do_wrapper.py", line 135, in _do_wrapper
    response = func(**request_kwargs)
               ^^^^^^^^^^^^^^^^^^^^^^
  File "C:\Users\aluga.com\Desktop\mvp-qualidade-seguranca-sistemas-inteligentes\exemplo_mvp\api\app.py", line 89, in predict
    avaliacao = Avaliacao(
                ^^^^^^^^^^
TypeError: __init__() got an unexpected keyword argument 'receita_total'
[2023-12-07 16:50:06,928] INFO _log() L224  127.0.0.1 - - [07/Dec/2023 16:50:06] "[35m[1mPOST /avaliacao HTTP/1.1[0m" 500 - - call_trace=C:\Python311\Lib\site-packages\werkzeug\_internal.py L224 
[2023-12-07 16:52:08,125] INFO _log() L224   * Running on all addresses (0.0.0.0)
   WARNING: This is a development server. Do not use it in a production deployment.
 * Running on http://127.0.0.1:5000
 * Running on http://192.168.0.179:5000 (Press CTRL+C to quit) - call_trace=C:\Python311\Lib\site-packages\werkzeug\_internal.py L224 
[2023-12-07 16:52:11,435] INFO _log() L224  127.0.0.1 - - [07/Dec/2023 16:52:11] "POST /avaliacao HTTP/1.1" 200 - - call_trace=C:\Python311\Lib\site-packages\werkzeug\_internal.py L224 
[2023-12-07 16:52:23,840] INFO _log() L224  127.0.0.1 - - [07/Dec/2023 16:52:23] "GET /avaliacoes HTTP/1.1" 200 - - call_trace=C:\Python311\Lib\site-packages\werkzeug\_internal.py L224 
[2023-12-07 16:56:15,710] INFO _log() L224   * Running on all addresses (0.0.0.0)
   WARNING: This is a development server. Do not use it in a production deployment.
 * Running on http://127.0.0.1:5000
 * Running on http://192.168.0.179:5000 (Press CTRL+C to quit) - call_trace=C:\Python311\Lib\site-packages\werkzeug\_internal.py L224 
