[2023-11-13 21:10:46,401] ERROR _log() L96   Error on request:
Traceback (most recent call last):
  File "/home/ubuntu/miniconda3/lib/python3.11/site-packages/werkzeug/serving.py", line 362, in run_wsgi
    execute(self.server.app)
  File "/home/ubuntu/miniconda3/lib/python3.11/site-packages/werkzeug/serving.py", line 323, in execute
    application_iter = app(environ, start_response)
                       ^^^^^^^^^^^^^^^^^^^^^^^^^^^^
  File "/home/ubuntu/miniconda3/lib/python3.11/site-packages/flask/cli.py", line 906, in app
    raise err from None
  File "/home/ubuntu/miniconda3/lib/python3.11/site-packages/flask/cli.py", line 897, in run_command
    app = info.load_app()
          ^^^^^^^^^^^^^^^
  File "/home/ubuntu/miniconda3/lib/python3.11/site-packages/flask/cli.py", line 312, in load_app
    app = locate_app(import_name, None, raise_if_not_found=False)
          ^^^^^^^^^^^^^^^^^^^^^^^^^^^^^^^^^^^^^^^^^^^^^^^^^^^^^^^
  File "/home/ubuntu/miniconda3/lib/python3.11/site-packages/flask/cli.py", line 223, in locate_app
    raise NoAppException(
flask.cli.NoAppException: While importing 'app', an ImportError was raised:

Traceback (most recent call last):
  File "/home/ubuntu/miniconda3/lib/python3.11/site-packages/flask/cli.py", line 218, in locate_app
    __import__(module_name)
  File "/mnt/g/My Drive/Doutorado/Teaching/SoftEng4IntSysPos/exemplo_mvp/api/app.py", line 9, in <module>
    from schemas import *
  File "/mnt/g/My Drive/Doutorado/Teaching/SoftEng4IntSysPos/exemplo_mvp/api/schemas/__init__.py", line 1, in <module>
    from schemas.paciente_schema import PacienteSchema,  PacienteBuscaSchema, PacienteViewSchema, PacienteDelSchema, \
ImportError: cannot import name 'predict_diabetes' from 'schemas.paciente_schema' (/mnt/g/My Drive/Doutorado/Teaching/SoftEng4IntSysPos/exemplo_mvp/api/schemas/paciente_schema.py) - call_trace=/home/ubuntu/miniconda3/lib/python3.11/site-packages/werkzeug/_internal.py L96  
[2023-11-13 21:10:47,018] INFO _log() L96   127.0.0.1 - - [13/Nov/2023 21:10:47] "[35m[1mGET /pacientes HTTP/1.1[0m" 500 - - call_trace=/home/ubuntu/miniconda3/lib/python3.11/site-packages/werkzeug/_internal.py L96  
[2023-11-13 21:10:47,040] ERROR _log() L96   Error on request:
Traceback (most recent call last):
  File "/home/ubuntu/miniconda3/lib/python3.11/site-packages/werkzeug/serving.py", line 362, in run_wsgi
    execute(self.server.app)
  File "/home/ubuntu/miniconda3/lib/python3.11/site-packages/werkzeug/serving.py", line 323, in execute
    application_iter = app(environ, start_response)
                       ^^^^^^^^^^^^^^^^^^^^^^^^^^^^
  File "/home/ubuntu/miniconda3/lib/python3.11/site-packages/flask/cli.py", line 906, in app
    raise err from None
  File "/home/ubuntu/miniconda3/lib/python3.11/site-packages/werkzeug/serving.py", line 362, in run_wsgi
    execute(self.server.app)
  File "/home/ubuntu/miniconda3/lib/python3.11/site-packages/werkzeug/serving.py", line 323, in execute
    application_iter = app(environ, start_response)
                       ^^^^^^^^^^^^^^^^^^^^^^^^^^^^
  File "/home/ubuntu/miniconda3/lib/python3.11/site-packages/flask/cli.py", line 906, in app
    raise err from None
  File "/home/ubuntu/miniconda3/lib/python3.11/site-packages/flask/cli.py", line 897, in run_command
    app = info.load_app()
          ^^^^^^^^^^^^^^^
  File "/home/ubuntu/miniconda3/lib/python3.11/site-packages/flask/cli.py", line 312, in load_app
    app = locate_app(import_name, None, raise_if_not_found=False)
          ^^^^^^^^^^^^^^^^^^^^^^^^^^^^^^^^^^^^^^^^^^^^^^^^^^^^^^^
  File "/home/ubuntu/miniconda3/lib/python3.11/site-packages/flask/cli.py", line 223, in locate_app
    raise NoAppException(
flask.cli.NoAppException: While importing 'app', an ImportError was raised:

Traceback (most recent call last):
  File "/home/ubuntu/miniconda3/lib/python3.11/site-packages/flask/cli.py", line 218, in locate_app
    __import__(module_name)
  File "/mnt/g/My Drive/Doutorado/Teaching/SoftEng4IntSysPos/exemplo_mvp/api/app.py", line 9, in <module>
    from schemas import *
  File "/mnt/g/My Drive/Doutorado/Teaching/SoftEng4IntSysPos/exemplo_mvp/api/schemas/__init__.py", line 1, in <module>
    from schemas.paciente_schema import PacienteSchema,  PacienteBuscaSchema, PacienteViewSchema, PacienteDelSchema, \
ImportError: cannot import name 'predict_diabetes' from 'schemas.paciente_schema' (/mnt/g/My Drive/Doutorado/Teaching/SoftEng4IntSysPos/exemplo_mvp/api/schemas/paciente_schema.py) - call_trace=/home/ubuntu/miniconda3/lib/python3.11/site-packages/werkzeug/_internal.py L96  
[2023-11-13 21:10:51,377] INFO _log() L96   127.0.0.1 - - [13/Nov/2023 21:10:51] "[35m[1mGET /pacientes HTTP/1.1[0m" 500 - - call_trace=/home/ubuntu/miniconda3/lib/python3.11/site-packages/werkzeug/_internal.py L96  
[2023-11-13 21:10:51,385] ERROR _log() L96   Error on request:
Traceback (most recent call last):
  File "/home/ubuntu/miniconda3/lib/python3.11/site-packages/werkzeug/serving.py", line 362, in run_wsgi
    execute(self.server.app)
  File "/home/ubuntu/miniconda3/lib/python3.11/site-packages/werkzeug/serving.py", line 323, in execute
    application_iter = app(environ, start_response)
                       ^^^^^^^^^^^^^^^^^^^^^^^^^^^^
  File "/home/ubuntu/miniconda3/lib/python3.11/site-packages/flask/cli.py", line 906, in app
    raise err from None
  File "/home/ubuntu/miniconda3/lib/python3.11/site-packages/werkzeug/serving.py", line 362, in run_wsgi
    execute(self.server.app)
  File "/home/ubuntu/miniconda3/lib/python3.11/site-packages/werkzeug/serving.py", line 323, in execute
    application_iter = app(environ, start_response)
                       ^^^^^^^^^^^^^^^^^^^^^^^^^^^^
  File "/home/ubuntu/miniconda3/lib/python3.11/site-packages/flask/cli.py", line 906, in app
    raise err from None
  File "/home/ubuntu/miniconda3/lib/python3.11/site-packages/werkzeug/serving.py", line 362, in run_wsgi
    execute(self.server.app)
  File "/home/ubuntu/miniconda3/lib/python3.11/site-packages/werkzeug/serving.py", line 323, in execute
    application_iter = app(environ, start_response)
                       ^^^^^^^^^^^^^^^^^^^^^^^^^^^^
  File "/home/ubuntu/miniconda3/lib/python3.11/site-packages/flask/cli.py", line 906, in app
    raise err from None
  File "/home/ubuntu/miniconda3/lib/python3.11/site-packages/flask/cli.py", line 897, in run_command
    app = info.load_app()
          ^^^^^^^^^^^^^^^
  File "/home/ubuntu/miniconda3/lib/python3.11/site-packages/flask/cli.py", line 312, in load_app
    app = locate_app(import_name, None, raise_if_not_found=False)
          ^^^^^^^^^^^^^^^^^^^^^^^^^^^^^^^^^^^^^^^^^^^^^^^^^^^^^^^
  File "/home/ubuntu/miniconda3/lib/python3.11/site-packages/flask/cli.py", line 223, in locate_app
    raise NoAppException(
flask.cli.NoAppException: While importing 'app', an ImportError was raised:

Traceback (most recent call last):
  File "/home/ubuntu/miniconda3/lib/python3.11/site-packages/flask/cli.py", line 218, in locate_app
    __import__(module_name)
  File "/mnt/g/My Drive/Doutorado/Teaching/SoftEng4IntSysPos/exemplo_mvp/api/app.py", line 9, in <module>
    from schemas import *
  File "/mnt/g/My Drive/Doutorado/Teaching/SoftEng4IntSysPos/exemplo_mvp/api/schemas/__init__.py", line 1, in <module>
    from schemas.paciente_schema import PacienteSchema,  PacienteBuscaSchema, PacienteViewSchema, PacienteDelSchema, \
ImportError: cannot import name 'predict_diabetes' from 'schemas.paciente_schema' (/mnt/g/My Drive/Doutorado/Teaching/SoftEng4IntSysPos/exemplo_mvp/api/schemas/paciente_schema.py) - call_trace=/home/ubuntu/miniconda3/lib/python3.11/site-packages/werkzeug/_internal.py L96  
[2023-11-13 21:10:54,563] INFO _log() L96   127.0.0.1 - - [13/Nov/2023 21:10:54] "[35m[1mGET /pacientes HTTP/1.1[0m" 500 - - call_trace=/home/ubuntu/miniconda3/lib/python3.11/site-packages/werkzeug/_internal.py L96  
